usage: gpt3gene.py [-h] [--key KEY] [--data_path DATA_PATH]
                   [--output_path OUTPUT_PATH] [--prompt PROMPT]
gpt3gene.py: error: unrecognized arguments: gpt3classi_res_arts_prompt2.out
the retina display display make pictures i took years ago jaw dropping.   The retina display display is a type of high-resolution display technology which makes pictures appear incredibly vivid and detailed, often making older pictures look even. Decide whether the "retina display display"'s sentiment is positive, neutral, or negative.
Traceback (most recent call last):
  File "gpt3gene.py", line 83, in <module>
    gene_sentence=generate_simple(prompt)
  File "gpt3gene.py", line 20, in generate_simple
    stop=".")
  File "/home/liuxinyu/anaconda3/envs/prefixnew/lib/python3.7/site-packages/openai/api_resources/completion.py", line 25, in create
    return super().create(*args, **kwargs)
  File "/home/liuxinyu/anaconda3/envs/prefixnew/lib/python3.7/site-packages/openai/api_resources/abstract/engine_api_resource.py", line 160, in create
    request_timeout=request_timeout,
  File "/home/liuxinyu/anaconda3/envs/prefixnew/lib/python3.7/site-packages/openai/api_requestor.py", line 225, in request
    request_timeout=request_timeout,
  File "/home/liuxinyu/anaconda3/envs/prefixnew/lib/python3.7/site-packages/openai/api_requestor.py", line 524, in request_raw
    timeout=request_timeout if request_timeout else TIMEOUT_SECS,
  File "/home/liuxinyu/anaconda3/envs/prefixnew/lib/python3.7/site-packages/requests/sessions.py", line 529, in request
    resp = self.send(prep, **send_kwargs)
  File "/home/liuxinyu/anaconda3/envs/prefixnew/lib/python3.7/site-packages/requests/sessions.py", line 645, in send
    r = adapter.send(request, **kwargs)
  File "/home/liuxinyu/anaconda3/envs/prefixnew/lib/python3.7/site-packages/requests/adapters.py", line 450, in send
    timeout=timeout
  File "/home/liuxinyu/anaconda3/envs/prefixnew/lib/python3.7/site-packages/urllib3/connectionpool.py", line 710, in urlopen
    chunked=chunked,
  File "/home/liuxinyu/anaconda3/envs/prefixnew/lib/python3.7/site-packages/urllib3/connectionpool.py", line 449, in _make_request
    six.raise_from(e, None)
  File "<string>", line 3, in raise_from
  File "/home/liuxinyu/anaconda3/envs/prefixnew/lib/python3.7/site-packages/urllib3/connectionpool.py", line 444, in _make_request
    httplib_response = conn.getresponse()
  File "/home/liuxinyu/anaconda3/envs/prefixnew/lib/python3.7/http/client.py", line 1373, in getresponse
    response.begin()
  File "/home/liuxinyu/anaconda3/envs/prefixnew/lib/python3.7/http/client.py", line 319, in begin
    version, status, reason = self._read_status()
  File "/home/liuxinyu/anaconda3/envs/prefixnew/lib/python3.7/http/client.py", line 280, in _read_status
    line = str(self.fp.readline(_MAXLINE + 1), "iso-8859-1")
  File "/home/liuxinyu/anaconda3/envs/prefixnew/lib/python3.7/socket.py", line 589, in readinto
    return self._sock.recv_into(b)
  File "/home/liuxinyu/anaconda3/envs/prefixnew/lib/python3.7/ssl.py", line 1071, in recv_into
    return self.read(nbytes, buffer)
  File "/home/liuxinyu/anaconda3/envs/prefixnew/lib/python3.7/ssl.py", line 929, in read
    return self._sslobj.read(len, buffer)
KeyboardInterrupt
usage: gpt3gene.py [-h] [--key KEY] [--data_path DATA_PATH]
                   [--output_path OUTPUT_PATH] [--prompt PROMPT]
gpt3gene.py: error: unrecognized arguments: gpt3classi_lap_test_prompt1new.out
